File: tether/data/ROPE1.DAT
 Instron DAT-file
 ================

Test data:
----------
Filename : 	rope1.DAT
Date : 	 1AUG12
User : 	bp
Sample ID : 	rope
Machine : 	4505
Test Type : 	Tensile
Method number : 	0   	Tensile               kvds            6/10/2010
Sample Temp : 	20	°C
Humidity : 	50	%
Speed : 	5	mm/min
Samplerate : 	10	pts/s
Specimen gauge length : 	400	mm
Grip distance : 	400	mm

Specimen data:
--------------
Specimen number : 	1
Specimen geometry : 	cylindrical
Surface : 	3.14	mm²
Diameter : 	2	mm
Extensometer removed at point :  0
Max Load : 	3.511917	kN
Displ. at Max Load : 	.365631	mm
Comment : 	red rope

Test results :
--------------
Point nr.	Time [s]	Displ [mm]	Load [kN]

0	0	-0.000051	0.174945
2	.2	-0.000051	0.174992
4	.4	0.006401	0.179954
6	.6	0.023292	0.198106
8	.8	0.040691	0.213329
10	1	0.057709	0.223416
12	1.2	0.075006	0.233544
14	1.4	0.091719	0.24144
16	1.6	0.108636	0.247773
18	1.8	0.125628	0.254254
20	2	0.142316	0.262093
22	2.2	0.159131	0.26699
24	2.4	0.175692	0.274242
26	2.6	0.191999	0.280609
28	2.8	0.208763	0.284837
30	3	0.225349	0.292154
32	3.2	0.24196	0.297031
34	3.4	0.259283	0.302884
36	3.6	0.275996	0.309884
38	3.8	0.291871	0.315305
40	4	0.309042	0.321844
42	4.2	0.325679	0.326699
44	4.4	0.342189	0.332568
46	4.6	0.358724	0.339258
48	4.8	0.375412	0.344163
50	5	0.391643	0.349222
52	5.2	0.408762	0.356496
54	5.4	0.424993	0.360187
56	5.6	0.441833	0.366632
58	5.8	0.4588	0.37335
60	6	0.475005	0.378912
62	6.2	0.491363	0.385231
64	6.4	0.508356	0.391231
66	6.6	0.524993	0.396352
68	6.8	0.541528	0.402041
70	7	0.558952	0.408213
72	7.2	0.576047	0.416223
74	7.4	0.592353	0.419235
76	7.6	0.609092	0.425432
78	7.8	0.625627	0.43004
80	8	0.642112	0.437222
82	8.2	0.659079	0.444667
84	8.4	0.67597	0.448645
86	8.6	0.69281	0.454991
88	8.8	0.709676	0.460936
90	9	0.726313	0.467232
92	9.2	0.743077	0.473179
94	9.4	0.759993	0.478957
96	9.6	0.776275	0.483899
98	9.8	0.792607	0.490521
100	10	0.809752	0.49715
102	10.2	0.82644	0.50203
104	10.4	0.843229	0.507438
106	10.6	0.860323	0.513843
108	10.8	0.877011	0.520278
110	11	0.893318	0.526381
112	11.2	0.910006	0.53238
114	11.4	0.926313	0.538025
116	11.6	0.942924	0.543876
118	11.8	0.959333	0.550616
120	12	0.97597	0.556193
122	12.2	0.992708	0.562914
124	12.4	1.009472	0.567738
126	12.6	1.026363	0.57565
128	12.8	1.042645	0.580357
130	13	1.059002	0.58675
132	13.2	1.075995	0.593559
134	13.4	1.092403	0.600356
136	13.6	1.108634	0.606584
138	13.8	1.125271	0.612362
140	14	1.142289	0.618348
142	14.2	1.159129	0.624923
144	14.4	1.175309	0.630746
146	14.6	1.191717	0.638404
148	14.8	1.20843	0.644524
150	15	1.224991	0.651291
152	15.2	1.241882	0.657588
154	15.4	1.258672	0.663235
156	15.6	1.27541	0.670753
158	15.8	1.291234	0.677422
160	16	1.308329	0.684622
162	16.2	1.324991	0.691333
164	16.4	1.341196	0.697171
166	16.6	1.358011	0.704965
168	16.8	1.374089	0.711928
170	17	1.390675	0.718047
172	17.2	1.407389	0.725464
174	17.4	1.423848	0.731544
176	17.6	1.440967	0.737132
178	17.8	1.45735	0.745184
180	18	1.473987	0.753038
182	18.2	1.490675	0.758894
184	18.4	1.507033	0.766104
186	18.6	1.524229	0.775386
188	18.8	1.540891	0.783774
190	19	1.557807	0.79086
192	19.2	1.573708	0.797451
194	19.4	1.590675	0.80462
196	19.6	1.607718	0.811096
198	19.8	1.624152	0.819781
200	20	1.640891	0.827158
202	20.2	1.657909	0.835692
204	20.4	1.674393	0.843215
206	20.6	1.691411	0.850864
208	20.8	1.708125	0.857882
210	21	1.72499	0.864634
212	21.2	1.741551	0.873178
214	21.4	1.758772	0.880014
216	21.6	1.775003	0.887923
218	21.8	1.791411	0.895555
220	22	1.808124	0.903157
222	22.2	1.824228	0.911404
224	22.4	1.840916	0.917833
226	22.6	1.857807	0.927305
228	22.8	1.874469	0.933963
230	23	1.891081	0.941487
232	23.2	1.907718	0.951339
234	23.4	1.924228	0.957138
236	23.6	1.940154	0.964572
238	23.8	1.956994	0.973429
240	24	1.972996	0.982349
242	24.2	1.989988	0.990591
244	24.4	2.007032	0.998547
246	24.6	2.023288	1.006888
248	24.8	2.04028	1.014031
250	25	2.057044	1.023445
252	25.2	2.073529	1.031729
254	25.4	2.090318	1.040727
256	25.6	2.106651	1.048761
258	25.8	2.123669	1.056977
260	26	2.139925	1.065084
262	26.2	2.156409	1.074113
264	26.4	2.172691	1.082272
266	26.6	2.189988	1.089269
268	26.8	2.206371	1.09885
270	27	2.222932	1.108025
272	27.2	2.239112	1.115757
274	27.4	2.256003	1.125171
276	27.6	2.272309	1.135117
278	27.8	2.288997	1.141655
280	28	2.30599	1.15329
282	28.2	2.322652	1.161105
284	28.4	2.338883	1.168789
286	28.6	2.356028	1.179152
288	28.8	2.372309	1.187415
290	29	2.389073	1.196017
292	29.2	2.40571	1.206515
294	29.4	2.421992	1.213799
296	29.6	2.438476	1.222927
298	29.8	2.455316	1.233972
300	30	2.471649	1.24137
302	30.2	2.489352	1.251566
304	30.4	2.50604	1.261168
306	30.6	2.522245	1.269322
308	30.8	2.539314	1.277986
310	31	2.555723	1.288828
312	31.2	2.572309	1.298988
314	31.4	2.589327	1.307944
316	31.6	2.605989	1.316056
318	31.8	2.622956	1.325981
320	32	2.639492	1.335166
322	32.2	2.656357	1.345247
324	32.4	2.673045	1.355318
326	32.6	2.690012	1.364326
328	32.8	2.706726	1.375012
330	33	2.723363	1.384041
332	33.2	2.739847	1.393289
334	33.4	2.757119	1.40448
336	33.6	2.773324	1.413035
338	33.8	2.790012	1.423523
340	34	2.807411	1.43115
342	34.2	2.823591	1.442972
344	34.4	2.839999	1.452173
346	34.6	2.856992	1.463192
348	34.8	2.872994	1.472591
350	35	2.890012	1.482292
352	35.2	2.90703	1.49181
354	35.4	2.923311	1.501267
356	35.6	2.939999	1.511681
358	35.8	2.956433	1.521961
360	36	2.972587	1.532834
362	36.2	2.990012	1.544802
364	36.4	3.006725	1.555399
366	36.6	3.023235	1.56486
368	36.8	3.039999	1.574915
370	37	3.057373	1.586107
372	37.2	3.073552	1.595683
374	37.4	3.090367	1.607291
376	37.6	3.10703	1.615887
378	37.8	3.123311	1.626286
380	38	3.139999	1.636133
382	38.2	3.156712	1.647283
384	38.4	3.17307	1.657036
386	38.6	3.189757	1.667258
388	38.8	3.206395	1.678418
390	39	3.22293	1.690578
392	39.2	3.239592	1.700769
394	39.4	3.256712	1.711616
396	39.6	3.272765	1.720869
398	39.8	3.289401	1.730382
400	40	3.306394	1.742397
402	40.2	3.323006	1.752264
404	40.4	3.339566	1.762132
406	40.6	3.356356	1.773699
408	40.8	3.372358	1.784264
410	41	3.389731	1.794299
412	41.2	3.405988	1.805292
414	41.4	3.42265	1.817473
416	41.6	3.439516	1.827216
418	41.8	3.45628	1.838699
420	42	3.473043	1.850036
422	42.2	3.490011	1.860841
424	42.4	3.50741	1.872355
426	42.6	3.523488	1.881327
428	42.8	3.540328	1.893821
430	43	3.557448	1.904751
432	43.2	3.573323	1.914661
434	43.4	3.59029	1.925842
436	43.6	3.607003	1.935876
438	43.8	3.623869	1.948276
440	44	3.640633	1.959852
442	44.2	3.657473	1.970804
444	44.4	3.674008	1.982599
446	44.6	3.691001	1.993686
448	44.8	3.707689	2.004638
450	45	3.723868	2.015485
452	45.2	3.740886	2.026238
454	45.4	3.757727	2.038982
456	45.6	3.774008	2.049402
458	45.8	3.79128	2.061823
460	46	3.808069	2.073472
462	46.2	3.824808	2.082871
464	46.4	3.841522	2.09524
466	46.6	3.858031	2.10616
468	46.8	3.874313	2.116497
470	47	3.89067	2.128834
472	47.2	3.907358	2.140484
474	47.4	3.923919	2.15031
476	47.6	3.940632	2.163825
478	47.8	3.957473	2.175047
480	48	3.973678	2.185748
482	48.2	3.990314	2.198659
484	48.4	4.007028	2.209297
486	48.6	4.023843	2.220218
488	48.8	4.040556	2.234118
490	49	4.057167	2.245715
492	49.2	4.073271	2.257501
494	49.4	4.090365	2.268233
496	49.6	4.107129	2.279029
498	49.8	4.123563	2.29049
500	50	4.140327	2.301057
502	50.2	4.15671	2.31503
504	50.4	4.173169	2.325564
506	50.6	4.18973	2.336068
508	50.8	4.206037	2.347874
510	51	4.222598	2.358929
512	51.2	4.239311	2.370287
514	51.4	4.256405	2.382916
516	51.6	4.272331	2.394108
518	51.8	4.289476	2.406236
520	52	4.305681	2.418084
522	52.2	4.322039	2.430192
524	52.4	4.338523	2.442644
526	52.6	4.355287	2.45446
528	52.8	4.372	2.466141
530	53	4.389044	2.477968
532	53.2	4.405732	2.488857
534	53.4	4.422318	2.501517
536	53.6	4.438879	2.51252
538	53.8	4.455363	2.524566
540	54	4.471848	2.536778
542	54.2	4.489069	2.549116
544	54.4	4.50568	2.559869
546	54.6	4.522318	2.571946
548	54.8	4.539234	2.583575
550	55	4.55643	2.596485
552	55.2	4.572686	2.608531
554	55.4	4.589729	2.621347
556	55.6	4.606036	2.631496
558	55.8	4.622927	2.644501
560	56	4.639411	2.655911
562	56.2	4.656709	2.668894
564	56.4	4.673092	2.680825
566	56.6	4.690008	2.69285
568	56.8	4.707052	2.704208
570	57	4.723638	2.715482
572	57.2	4.740326	2.72809
574	57.4	4.756988	2.741136
576	57.6	4.77327	2.752734
578	57.8	4.790008	2.764957
580	58	4.807128	2.776231
582	58.2	4.823612	2.787036
584	58.4	4.840605	2.799353
586	58.6	4.856988	2.811128
588	58.8	4.873371	2.823715
590	59	4.890008	2.83402
592	59.2	4.906366	2.848515
594	59.4	4.922952	2.858393
596	59.6	4.939513	2.872522
598	59.8	4.956327	2.883359
600	60	4.97304	2.895717
602	60.2	4.990008	2.908294
604	60.4	5.00667	2.918673
606	60.6	5.023231	2.931802
608	60.8	5.039995	2.943108
610	61	5.056404	2.955507
612	61.2	5.072685	2.968574
614	61.4	5.089754	2.981652
616	61.6	5.106365	2.991519
618	61.8	5.123281	3.003919
620	62	5.139995	3.015589
622	62.2	5.156276	3.01859
624	62.4	5.17271	3.031366
626	62.6	5.189398	3.041535
628	62.8	5.206035	3.054612
630	63	5.222316	3.057853
632	63.2	5.23875	3.062302
634	63.4	5.255997	3.076505
636	63.6	5.272329	3.087446
638	63.8	5.289474	3.100054
640	64	5.305958	3.111558
642	64.2	5.322291	3.119436
644	64.4	5.338521	3.107723
646	64.6	5.355361	3.118248
648	64.8	5.371287	3.128293
650	65	5.388	3.139171
652	65.2	5.404993	3.150779
654	65.4	5.421401	3.1642
656	65.6	5.438242	3.176246
658	65.8	5.455006	3.188666
660	66	5.471668	3.199899
662	66.2	5.488686	3.212778
664	66.4	5.504993	3.20713
666	66.6	5.522392	2.238297
668	66.8	5.539207	2.244121
670	67	5.556428	2.261533
672	67.2	5.572633	2.279143
674	67.4	5.589803	2.297253
676	67.6	5.606008	2.317614
678	67.8	5.622671	2.332639
680	68	5.639029	2.32099
682	68.2	5.656047	2.287885
684	68.4	5.672328	2.280748
686	68.6	5.689397	2.276059
688	68.8	5.706313	2.279664
690	69	5.723331	2.287583
692	69.2	5.739994	2.220999
694	69.4	5.757011	1.729194
696	69.6	5.773725	1.723088
698	69.8	5.790006	1.735905
700	70	5.80705	1.752358
702	70.2	5.823509	1.77151
704	70.4	5.840324	1.78936
706	70.6	5.857087	1.808814
708	70.8	5.873648	1.827695
710	71	5.890412	1.847431
712	71.2	5.90705	1.863602
714	71.4	5.92295	1.879337
716	71.6	5.939561	1.895988
718	71.8	5.956402	1.912889
720	72	5.972353	1.928332
722	72.2	5.989396	1.942555
724	72.4	6.006313	1.956601
726	72.6	6.023	1.968022
728	72.8	6.039993	1.977369
730	73	6.056402	1.990029
732	73.2	6.072683	2.000324
734	73.4	6.089828	2.01139
736	73.6	6.105677	2.022373
738	73.8	6.122645	2.030198
740	74	6.138951	2.041275
742	74.2	6.155715	2.054977
744	74.4	6.171641	2.068367
746	74.6	6.188685	2.082569
748	74.8	6.205322	2.097074
750	75	6.221679	2.112193
752	75.2	6.237834	2.127167
754	75.4	6.254369	2.14139
756	75.6	6.271311	2.155166
758	75.8	6.288405	2.171004
760	76	6.304991	2.18554
762	76.2	6.322035	2.194678
764	76.4	6.338316	2.204567
766	76.6	6.354471	2.219957
768	76.8	6.37065	2.236233
770	77	6.387769	2.248852
772	77.2	6.404356	2.261335
774	77.4	6.420993	2.269129
776	77.6	6.437909	2.281602
778	77.8	6.454445	2.293387
780	78	6.471031	2.303578
782	78.2	6.488074	2.316822
784	78.4	6.504711	2.329524
786	78.6	6.521044	2.340819
788	78.8	6.537198	2.355584
790	79	6.554166	2.369516
792	79.2	6.570599	2.383687
794	79.4	6.587719	2.394857
796	79.6	6.604127	2.404423
798	79.8	6.620764	2.414895
800	80	6.637172	2.426472
802	80.2	6.654114	2.419636
804	80.4	6.670675	2.410821
806	80.6	6.687769	2.409696
808	80.8	6.704406	2.406809
810	81	6.72112	2.397192
812	81.2	6.737833	2.39566
814	81.4	6.7548	2.397421
816	81.6	6.771412	2.408841
818	81.8	6.788353	2.409154
820	82	6.804991	2.412947
822	82.2	6.821348	2.422502
824	82.4	6.837756	2.14784
826	82.6	6.854723	2.142338
828	82.8	6.87136	2.153863
830	83	6.888709	2.058311
832	83.2	6.905396	2.023446
834	83.4	6.921729	2.028177
836	83.6	6.938188	2.0439
838	83.8	6.954748	2.061375
840	84	6.971309	2.078933
842	84.2	6.988353	2.098501
844	84.4	7.00499	2.115934
846	84.6	7.021677	2.13519
848	84.8	7.038162	2.152904
850	85	7.055003	2.168691
852	85.2	7.071589	2.18678
854	85.4	7.088709	2.201952
856	85.6	7.104761	2.216498
858	85.8	7.121398	2.23267
860	86	7.137248	2.244809
862	86.2	7.154012	2.259241
864	86.4	7.170268	2.274735
866	86.6	7.187362	2.287667
868	86.8	7.204431	2.300587
870	87	7.221042	2.312424
872	87.2	7.236917	2.325762
874	87.4	7.253453	2.339496
876	87.6	7.269988	2.350895
878	87.8	7.287082	2.363316
880	88	7.30377	2.375612
882	88.2	7.320356	2.388084
884	88.4	7.336688	2.400714
886	88.6	7.353351	2.413207
888	88.8	7.369988	2.42567
890	89	7.386752	2.438215
892	89.2	7.403033	2.45049
894	89.4	7.419162	2.46065
896	89.6	7.43585	2.474008
898	89.8	7.452716	2.48572
900	90	7.469708	2.497558
902	90.2	7.487006	2.510645
904	90.4	7.503795	2.520732
906	90.6	7.52	2.531892
908	90.8	7.536206	2.543479
910	91	7.553122	2.554836
912	91.2	7.570012	2.566538
914	91.4	7.587005	2.57751
916	91.6	7.603363	2.58792
918	91.8	7.620686	2.599465
920	92	7.636764	2.609417
922	92.2	7.654087	2.622212
924	92.4	7.670673	2.633216
926	92.6	7.68731	2.64299
928	92.8	7.704125	2.654796
930	93	7.720685	2.665362
932	93.2	7.737247	2.67747
934	93.4	7.753756	2.687223
936	93.6	7.770368	2.698164
938	93.8	7.788047	2.708397
940	94	7.804836	2.721213
942	94.2	7.820965	2.732133
944	94.4	7.83717	2.741386
946	94.6	7.85368	2.752984
948	94.8	7.870317	2.763445
950	95	7.887309	2.773761
952	95.2	7.904124	2.785088
954	95.4	7.920685	2.795195
956	95.6	7.937246	2.804855
958	95.8	7.953807	2.817098
960	96	7.970012	2.827362
962	96.2	7.987005	2.838303
964	96.4	8.003769	2.849338
966	96.6	8.020279	2.859789
968	96.8	8.03689	2.870469
970	97	8.05368	2.882161
972	97.2	8.070647	2.8928
974	97.4	8.087639	2.902876
976	97.6	8.104073	2.912285
978	97.8	8.120685	2.921913
980	98	8.136992	2.932073
982	98.2	8.153807	2.94342
984	98.4	8.170011	2.951516
986	98.6	8.18703	2.962666
988	98.8	8.203362	2.972044
990	99	8.220354	2.981558
992	99.2	8.23661	2.991717
994	99.4	8.253069	3.000241
996	99.6	8.270011	3.009244
998	99.8	8.28609	3.016673
1000	100	8.302726	3.027281
1002	100.2	8.319211	3.037961
1004	100.4	8.335925	3.046527
1006	100.6	8.352409	3.056405
1008	100.8	8.369681	3.063928
1010	101	8.386318	3.077047
1012	101.2	8.402726	3.086341
1014	101.4	8.41883	3.095261
1016	101.6	8.435924	3.104472
1018	101.8	8.452282	3.113996
1020	102	8.46968	3.123958
1022	102.2	8.486724	3.13344
1024	102.4	8.503361	3.143047
1026	102.6	8.520709	3.151696
1028	102.8	8.537473	3.160866
1030	103	8.553831	3.170098
1032	103.2	8.570316	3.1766
1034	103.4	8.58741	3.185374
1036	103.6	8.604072	3.194376
1038	103.8	8.621039	3.202108
1040	104	8.636889	3.210027
1042	104.2	8.654085	3.220052
1044	104.4	8.671001	3.229117
1046	104.6	8.68835	3.23714
1048	104.8	8.705012	3.24804
1050	105	8.721725	3.255521
1052	105.2	8.737803	3.261565
1054	105.4	8.754517	3.271235
1056	105.6	8.771077	3.278612
1058	105.8	8.788045	3.287302
1060	106	8.805012	3.297285
1062	106.2	8.82175	3.305162
1064	106.4	8.838159	3.315603
1066	106.6	8.854999	3.322876
1068	106.8	8.87095	3.331171
1070	107	8.8884	3.338965
1072	107.2	8.904757	3.346967
1074	107.4	8.921369	3.354657
1076	107.6	8.937803	3.362097
1078	107.8	8.954491	3.373184
1080	108	8.97133	3.380853
1082	108.2	8.988552	3.390627
1084	108.4	9.004732	3.398067
1086	108.6	9.021369	3.405424
1088	108.8	9.037599	3.415281
1090	109	9.054363	3.421992
1092	109.2	9.071051	3.429869
1094	109.4	9.088044	3.438747
1096	109.6	9.105011	3.445708
1098	109.8	9.121317	3.454252
1100	110	9.137599	3.460546
1102	110.2	9.153753	3.468194
1104	110.4	9.170365	3.474259
1106	110.6	9.187028	3.480323
1108	110.8	9.203792	3.487179
1110	111	9.220708	3.494536
1112	111.2	9.236837	3.500246
1114	111.4	9.253804	3.505081
1116	111.6	9.270289	3.508437
1118	111.8	9.287028	3.511917
1120	112	9.30341	3.510791
1122	112.2	9.319996	3.496183
1124	112.4	9.336202	3.454961
1126	112.6	9.353093	3.39763
1128	112.8	9.370009	3.330191
1130	113	9.387027	3.24656
1132	113.2	9.403766	3.176454
1134	113.4	9.420326	3.107244
1136	113.6	9.436532	3.014464
1138	113.8	9.453448	2.840512
1140	114	9.470009	2.761382
1142	114.2	9.487357	2.724933
1144	114.4	9.504121	2.705739
1146	114.6	9.520606	2.691443
1148	114.8	9.53709	2.678689
1150	115	9.554108	2.669999
1152	115.2	9.570644	2.647231
1154	115.4	9.587763	2.343737
1156	115.6	9.6044	2.027708
1158	115.8	9.621368	1.934855
1160	116	9.637751	1.89826
1162	116.2	9.654998	1.879274
1164	116.4	9.671964	1.861914
1166	116.6	9.689109	1.84866
1168	116.8	9.705365	1.8432
1170	117	9.722332	1.839626
1172	117.2	9.738513	1.840908
1174	117.4	9.755352	1.843148
1176	117.6	9.771279	1.844023
1178	117.8	9.788398	1.845617
1180	118	9.80501	1.849734
1182	118.2	9.821672	1.852818
1184	118.4	9.838208	1.85684
1186	118.6	9.854997	1.788828
1188	118.8	9.871354	1.723099
1190	119	9.888398	1.642125
1192	119.2	9.904806	1.593359
1194	119.4	9.921037	1.472216
1196	119.6	9.937395	1.393029
1198	119.8	9.954159	1.368239
1200	120	9.970389	1.355407
1202	120.2	9.988068	1.347738
1204	120.4	10.004832	1.343262
1206	120.6	10.021011	1.342757
1208	120.8	10.03747	1.343413
1210	121	10.053726	1.344732
1212	121.2	10.070288	1.345362
1214	121.4	10.088042	1.348446
1216	121.6	10.104044	1.349587
1218	121.8	10.121036	1.353349
1220	122	10.137572	1.354787
1222	122.2	10.153803	1.359163
1224	122.4	10.170007	1.361539
1226	122.6	10.187051	1.36304
1228	122.8	10.203434	1.367135
1230	123	10.219842	1.369193
1232	123.2	10.236632	1.371563
1234	123.4	10.25271	1.374241
1236	123.6	10.270007	1.376893
1238	123.8	10.286949	1.379816
1240	124	10.303434	1.381129
1242	124.2	10.319994	1.381665
1244	124.4	10.336149	1.384495
1246	124.6	10.35276	1.385167
1248	124.8	10.369449	1.388371
1250	125	10.386492	1.389955
1252	125.2	10.403078	1.391721
1254	125.4	10.419994	1.392226
1256	125.6	10.43653	1.393174
1258	125.8	10.452685	1.394227
1260	126	10.469728	1.395227
1262	126.2	10.486009	1.397222
1264	126.4	10.502569	1.398572
1266	126.6	10.518801	1.400323
1268	126.8	10.535869	1.40224
1270	127	10.55243	1.403928
1272	127.2	10.570006	1.405173
1274	127.4	10.586999	1.406569
1276	127.6	10.603357	1.406616
1278	127.8	10.619435	1.407366
1280	128	10.635869	1.40945
1282	128.2	10.652607	1.409956
1284	128.4	10.670006	1.41155
1286	128.6	10.686669	1.413108
1288	128.8	10.703407	1.412597
1290	129	10.719994	1.412561
1292	129.2	10.736758	1.414786
1294	129.4	10.75375	1.416281
1296	129.6	10.770006	1.414426
1298	129.8	10.787126	1.416911
1300	130	10.803484	1.417547
1302	130.2	10.820324	1.419016
1304	130.4	10.836605	1.419735
1306	130.6	10.853369	1.421345
1308	130.8	10.870311	1.42258
1310	131	10.887761	1.423163
1312	131.2	10.904067	1.424174
1314	131.4	10.920323	1.423585
1316	131.6	10.936834	1.424685
1318	131.8	10.953089	1.427472
1320	132	10.970006	1.429681
1322	132.2	10.98705	1.430853
1324	132.4	11.003788	1.43152
1326	132.6	11.020679	1.431067
1328	132.8	11.037468	1.434334
1330	133	11.05408	1.434901
1332	133.2	11.070641	1.435923
1334	133.4	11.087633	1.437105
1336	133.6	11.104372	1.438028
1338	133.8	11.121364	1.437282
1340	134	11.137189	1.439726
1342	134.2	11.154131	1.439273
1344	134.4	11.170361	1.440085
1346	134.6	11.187328	1.43983
1348	134.8	11.203762	1.441393
1350	135	11.220678	1.441768
1352	135.2	11.236757	1.440476
1354	135.4	11.253393	1.440742
1356	135.6	11.270005	1.441028
1358	135.8	11.287074	1.44305
1360	136	11.303711	1.442529
1362	136.2	11.320399	1.444029
1364	136.4	11.336833	1.443805
1366	136.6	11.353368	1.44517
1368	136.8	11.370005	1.447218
1370	137	11.386642	1.446197
1372	137.2	11.403787	1.448156
1374	137.4	11.420322	1.449041
1376	137.6	11.436909	1.449469
1378	137.8	11.453368	1.451907
1380	138	11.470005	1.448963
1382	138.2	11.487074	1.448739
1384	138.4	11.503431	1.446515
1386	138.6	11.519992	1.447202
1388	138.8	11.536197	1.445509
1390	139	11.553165	1.445764
1392	139.2	11.570004	1.442935
1394	139.4	11.586693	1.442633
1396	139.6	11.603406	1.441529
1398	139.8	11.620322	1.433578
1400	140	11.636476	1.422663
1402	140.2	11.653723	1.412853
1404	140.4	11.671072	1.398015
1406	140.6	11.688089	1.374074
1408	140.8	11.704726	1.309762
1410	141	11.721668	1.19957
1412	141.2	11.738077	1.092817
1414	141.4	11.754993	1.036809
1416	141.6	11.772011	1.003887
1418	141.8	11.789131	0.982083
1420	142	11.805285	0.963525
1422	142.2	11.822049	0.950677
1424	142.4	11.838204	0.940174
1426	142.6	11.854993	0.930514
1428	142.8	11.87163	0.923366
1430	143	11.888724	0.918156
1432	143.2	11.90531	0.911956
1434	143.4	11.921668	0.908512
1436	143.6	11.938127	0.903896
1438	143.8	11.954764	0.900552
1440	144	11.971324	0.898129
1442	144.2	11.988013	0.893737
1444	144.4	12.004828	0.890726
1446	144.6	12.021363	0.889548
1448	144.8	12.038229	0.887745
1450	145	12.055399	0.884645
1452	145.2	12.071629	0.88427
1454	145.4	12.088673	0.882822
1456	145.6	12.105005	0.879336
1458	145.8	12.121312	0.878008
1460	146	12.137593	0.875439
1462	146.2	12.154154	0.873204
1464	146.4	12.170639	0.870485
1466	146.6	12.187682	0.870162
1468	146.8	12.204395	0.868067
1470	147	12.221032	0.866171
1472	147.2	12.237161	0.866478
1474	147.4	12.253722	0.864509
1476	147.6	12.270003	0.862091
1478	147.8	12.286691	0.859721
1480	148	12.303354	0.85784
1482	148.2	12.31999	0.856662
1484	148.4	12.336602	0.85487
1486	148.6	12.353671	0.853672
1488	148.8	12.370003	0.851973
1490	149	12.386361	0.850744
1492	149.2	12.403125	0.848988
1494	149.4	12.419228	0.848993
1496	149.6	12.435967	0.84605
1498	149.8	12.45235	0.843997
1500	150	12.469724	0.843747
1502	150.2	12.48664	0.842809
1504	150.4	12.503404	0.842064
1506	150.6	12.52032	0.839037
1508	150.8	12.536551	0.838735
1510	151	12.553112	0.837807
1512	151.2	12.570002	0.837979
1514	151.4	12.586767	0.836072
1516	151.6	12.60315	0.833759
1518	151.8	12.61999	0.83254
1520	152	12.636474	0.830831
1522	152.2	12.653442	0.831087
1524	152.4	12.670002	0.829096
1526	152.6	12.687122	0.828429
1528	152.8	12.703531	0.827257
1530	153	12.72032	0.827142
1532	153.2	12.73683	0.826179
1534	153.4	12.753771	0.824423
1536	153.6	12.770002	0.822662
1538	153.8	12.787351	0.822031
1540	154	12.804165	0.821339
1542	154.2	12.82032	0.81915
1544	154.4	12.83688	0.817697
1546	154.6	12.853314	0.817186
1548	154.8	12.870002	0.814842
1550	155	12.887351	0.813664
1552	155.2	12.903708	0.811153
1554	155.4	12.92037	0.809184
1556	155.6	12.93683	0.807626
1558	155.8	12.953111	0.807532
1560	156	12.970002	0.805047
1562	156.2	12.986639	0.803958
1564	156.4	13.003047	0.803515
1566	156.6	13.019989	0.801071
1568	156.8	13.03655	0.800556
1570	157	13.053441	0.799264
1572	157.2	13.070408	0.797659
1574	157.4	13.087351	0.79471
1576	157.6	13.103682	0.794142
1578	157.8	13.120269	0.792694
1580	158	13.136245	0.790089
1582	158.2	13.152679	0.788739
1584	158.4	13.169392	0.787796
1586	158.6	13.186359	0.786457
1588	158.8	13.202793	0.783701
1590	159	13.219277	0.783279
1592	159.2	13.23589	0.780284
1594	159.4	13.252882	0.779747
1596	159.6	13.269392	0.778486
1598	159.8	13.285953	0.776793
1600	160	13.302361	0.777121
1602	160.2	13.318567	0.775766
1604	160.4	13.335331	0.776105
1606	160.6	13.351992	0.772208
1608	160.8	13.369392	0.772265
1610	161	13.386079	0.771463
1612	161.2	13.402793	0.769983
1614	161.4	13.418871	0.768457
1616	161.6	13.435279	0.767498
1618	161.8	13.452043	0.766144
1620	162	13.46901	0.765576
1622	162.2	13.486003	0.764898
1624	162.4	13.502767	0.764549
1626	162.6	13.519328	0.763705
1628	162.8	13.536524	0.762872
1630	163	13.552729	0.762955
1632	163.2	13.57	0.763648
1634	163.4	13.586993	0.761653
1636	163.6	13.603757	0.761168
1638	163.8	13.620394	0.760741
1640	164	13.636447	0.761356
1642	164.2	13.653847	0.760642
1644	164.4	13.670712	0.760027
1646	164.6	13.68773	0.760006
1648	164.8	13.704392	0.759829
1650	165	13.720953	0.75861
1652	165.2	13.737132	0.75761
1654	165.4	13.754151	0.759074
1656	165.6	13.770686	0.757417
1658	165.8	13.787552	0.757552
1660	166	13.804849	0.757604
1662	166.2	13.82136	0.756854
1664	166.4	13.83792	0.757594
1666	166.6	13.854354	0.757401
1668	166.8	13.870635	0.758401
1670	167	13.888035	0.757698
1672	167.2	13.904113	0.758339
1674	167.4	13.920673	0.756307
1676	167.6	13.936802	0.755984
1678	167.8	13.954073	0.757547
1680	168	13.970356	0.755823
1682	168.2	13.987399	0.756885
1684	168.4	14.004113	0.75724
1686	168.6	14.020724	0.756552
1688	168.8	14.036522	0.756114
1690	169	14.053439	0.756781
1692	169.2	14.07	0.759094
1694	169.4	14.086993	0.757156
1696	169.6	14.10368	0.755281
1698	169.8	14.120292	0.755062
1700	170	14.136522	0.755036
1702	170.2	14.153109	0.753937
1704	170.4	14.17	0.753926
1706	170.6	14.186687	0.753671
1708	170.8	14.20335	0.753884
1710	171	14.220291	0.754239
1712	171.2	14.236548	0.751821
1714	171.4	14.253718	0.752551
1716	171.6	14.270227	0.752504
1718	171.8	14.287043	0.751462
1720	172	14.30335	0.752707
1721	172.1	14.311274	0.752915